Workbook

Sheet Albañileria
A1: Cafferata 500 | B1: LARGO | C1: ANCHO | D1: ALTURA | E1: SUPERFICIE | F1: PERIMETRO | G1: SUPERFICIE LATERAL | H1: GRUESOS INTERIORES | I1: CONTRAPISO DE 0,10 | J1: =J2/I2 -> 0.1719485 | K1: CARPETA + IMPERM | L1: CARPETAS ESCALERAS | M1: CARPETAS DE CEMENTO | N1: ENLUCIDO A LA CAL | O1: ENDUIDO | P1: BUÑAS EN CIELORRASOS | Q1: CIELORRASO APLICADO | R1: CIELORRASO SUSPENDIDO | S1: CANTONERA | T1: REVEST. CERAMICOS | U1: PISO PORCELANATO | V1: ZOC. PORCELANATO | W1: ZOC. PVC | X1: PISO CERAMICO | Y1: ZOC. CERAMICO | Z1: LATEX INTERIOR | AA1: LATEX CIELORRASOS | AB1: MESADA GRANITO | AC1: ZOCALO DUCHA
A2: TOTALES | H2: =H3+H10+H31 -> 1624.042 | I2: =I3+I10+I31 -> 238.0015 | J2: =J3+J10+J31 -> 40.924 | K2: =K3+K10+K31 -> 12.975 | L2: =L3+L10+L31 -> 150.416 | M2: =M3+M10+M31 -> 225.0265 | N2: =N3+N10+N31 -> 516.4 | O2: =O3+O10+O31 -> 791.382 | ... AC2: =AC3+AC10+AC31 -> 1.35
A3: PLANTA BAJA | H3: =SUM(H4:H8) -> 449.44 | I3: =SUM(I4:I8) -> 40.924 | J3: =SUM(J4:J8) -> 40.924 | K3: =SUM(K4:K8) -> 0 | L3: =SUM(L4:L8) -> 0 | M3: =SUM(M4:M8) -> 40.924 | N3: =SUM(N4:N8) -> 42.88 | O3: =SUM(O4:O8) -> 146.08 | ... AC3: =SUM(AC4:AC8) -> 0
A4: INGRESO VEHICULAR | B4: 3 | C4: 9.8 | D4: 4 | E4: =+B4*C4 -> 29.4 | F4: =+(B4+C4)*2 -> 25.6 | G4: =+F4*D4 -> 102.4 | H4: =+G4 -> 102.4 | R4: =+E4 -> 29.4 | Z4: =+N4+O4 -> 0 | AA4: =+Q4+R4 -> 29.4
A5: COCHERA | B5: 11.4 | C5: 8.36 | D5: 4 | E5: =+B5*C5 -> 95.304 | F5: =+(B5+C5)*2 -> 39.52 | G5: =+F5*D5 -> 158.08 | H5: =+G5 -> 158.08 | R5: =7.21*8.36 -> 60.2756 | Z5: =+N5+O5 -> 0 | AA5: =+Q5+R5 -> 60.2756
A6: HALL INGRESO | B6: 7.7 | C6: 2.6 | D6: 4 | E6: =+B6*C6 -> 20.02 | F6: =+(B6+C6)*2 -> 20.6 | G6: =+F6*D6 -> 82.4 | H6: =+G6 -> 82.4 | I6: =+E6 -> 20.02 | J6: =I6 -> 20.02 | M6: =+E6 -> 20.02 | O6: =+G6-T6 -> 82.4 | P6: =+F6 -> 20.6 | R6: =+E6 -> 20.02 | S6: 7 | U6: =+M6+K6 -> 20.02 | V6: =+F6 -> 20.6 | Z6: =+N6+O6 -> 82.4 | AA6: =+Q6+R6 -> 20.02
A7: COCHERA | B7: 5.4 | C7: 2.56 | D7: 4 | E7: =+B7*C7 -> 13.824 | F7: =+(B7+C7)*2 -> 15.92 | G7: =+F7*D7 -> 63.68 | H7: =+G7 -> 63.68 | I7: =+E7 -> 13.824 | J7: =I7 -> 13.824 | M7: =+E7 -> 13.824 | O7: =+G7-T7 -> 63.68 | P7: =+F7 -> 15.92 | R7: =+E7 -> 13.824 | X7: =+E7 -> 13.824 | Y7: =+F7 -> 15.92 | Z7: =+N7+O7 -> 63.68 | AA7: =+Q7+R7 -> 13.824
A8: SALA DE BOMBAS | B8: 3 | C8: 2.36 | D8: 4 | E8: =+B8*C8 -> 7.08 | F8: =+(B8+C8)*2 -> 10.72 | G8: =+F8*D8 -> 42.88 | H8: =+G8 -> 42.88 | I8: =+E8 -> 7.08 | J8: =I8 -> 7.08 | M8: =+E8 -> 7.08 | N8: =+G8 -> 42.88 | Q8: =+E8 -> 7.08 | X8: =+E8 -> 7.08 | Y8: =+F8 -> 10.72 | Z8: =+N8+O8 -> 42.88 | AA8: =+Q8+R8 -> 7.08
A10: PLANTA 1° AL 10° PISO | H10: =+H11+H17+H22 -> 350.622 | I10: =+I11+I17+I22 -> 103.2775 | J10: =+J11+J17+J22 -> 0 | K10: =+K11+K17+K22 -> 12.975 | L10: =+L11+L17+L22 -> 0 | M10: =+M11+M17+M22 -> 90.3025 | N10: =+N11+N17+N22 -> 0 | O10: =+O11+O17+O22 -> 294.842 | ... AC10: =+AC11+AC17+AC22 -> 1.35
A11: DPTO A | H11: =SUM(H12:H16) -> 109.944 | I11: =SUM(I12:I16) -> 36.216 | J11: =SUM(J12:J16) -> 0 | K11: =SUM(K12:K16) -> 8.1 | L11: =SUM(L12:L16) -> 0 | M11: =SUM(M12:M16) -> 28.116 | N11: =SUM(N12:N16) -> 0 | O11: =SUM(O12:O16) -> 92.089 | ... AC11: =SUM(AC12:AC16) -> 0.45
A12: COCINA COMEDOR | B12: 2.5 | C12: 5.6 | D12: 2.7 | E12: =+B12*C12 -> 14 | F12: =+(B12+C12)*2 -> 16.2 | G12: =+F12*D12 -> 43.74 | H12: =+G12 -> 43.74 | I12: =+E12 -> 14 | M12: =+E12 -> 14 | O12: =+G12-T12 -> 39.825 | P12: =+F12 -> 16.2 | Q12: =+E12-2.1*2.5 -> 8.75 | R12: =2.1*2.5+2.5+6 -> 13.75 | S12: 4 | T12: =+(0.6*2+1.5)*1.45 -> 3.915 | U12: =+M12+K12 -> 14 | W12: =+F12-V12 -> 16.2 | Z12: =+N12+O12 -> 39.825 | AA12: =+Q12+R12 -> 22.5 | AB12: =+(1.5*2)*0.7 -> 2.1
A13: PASO | B13: 1 | C13: 1 | D13: 2.7 | E13: =+B13*C13 -> 1 | F13: =+(B13+C13)*2 -> 4 | G13: =+F13*D13 -> 10.8 | H13: =+G13 -> 10.8 | I13: =+E13 -> 1 | M13: =+E13 -> 1 | O13: =+G13-T13 -> 10.8 | P13: =+F13 -> 4 | Q13: =+E13 -> 1 | S13: 2 | U13: =+M13+K13 -> 1 | W13: =+F13-V13 -> 4 | Z13: =+N13+O13 -> 10.8 | AA13: =+Q13+R13 -> 1
A14: DORMITORIO | B14: 2.56 | C14: 3.6 | D14: 2.7 | E14: =+B14*C14 -> 9.216 | F14: =+(B14+C14)*2 -> 12.32 | G14: =+F14*D14 -> 33.264 | H14: =+G14 -> 33.264 | I14: =+E14 -> 9.216 | M14: =+E14 -> 9.216 | O14: =+G14-T14 -> 33.264 | P14: =+F14 -> 12.32 | Q14: =+E14 -> 9.216 | R14: 6 | S14: 2 | U14: =+M14+K14 -> 9.216 | W14: =+F14-V14 -> 12.32 | Z14: =+N14+O14 -> 33.264 | AA14: =+Q14+R14 -> 15.216
A15: BAÑO | B15: 2.6 | C15: 1.5 | D15: 2.7 | E15: =+B15*C15 -> 3.9 | F15: =+(B15+C15)*2 -> 8.2 | G15: =+F15*D15 -> 22.14 | H15: =+G15 -> 22.14 | I15: =+E15 -> 3.9 | M15: =+E15-K15 -> 3.9 | O15: =+F15 -> 8.2 | P15: =+F15 -> 8.2 | R15: =+E15 -> 3.9 | T15: =+F15*2.4 -> 19.68 | U15: =+M15+K15 -> 3.9 | Z15: =+N15+O15 -> 8.2 | AA15: =+Q15+R15 -> 3.9 | AC15: =1.5*0.15*2 -> 0.45
A16: BALCON FRENTE | B16: 1.5 | C16: 5.4 | D16: 2.7 | E16: =+B16*C16 -> 8.1 | F16: =+(B16+C16)*2 -> 13.8 | G16: =+F16*D16 -> 37.26 | I16: =+E16 -> 8.1 | K16: =+E16 -> 8.1 | X16: =+E16 -> 8.1 | Y16: =+F16 -> 13.8
A17: DPTO B | H17: =SUM(H18:H21) -> 87.48 | I17: =SUM(I18:I21) -> 29.275 | J17: =SUM(J18:J21) -> 0 | K17: =SUM(K18:K21) -> 4.875 | L17: =SUM(L18:L21) -> 0 | M17: =SUM(M18:M21) -> 24.4 | N17: =SUM(N18:N21) -> 0 | O17: =SUM(O18:O21) -> 72.195 | ... AC17: =SUM(AC18:AC21) -> 0.45
A18: MONOAMBIENTE | B18: 6 | C18: 3 | D18: 2.7 | E18: =+B18*C18 -> 18 | F18: =+(B18+C18)*2 -> 18 | G18: =+F18*D18 -> 48.6 | H18: =+G18 -> 48.6 | I18: =+E18 -> 18 | M18: =+E18 -> 18 | O18: =+G18-T18 -> 48.6 | P18: =+F18 -> 18 | Q18: =+E18 -> 18 | S18: 2 | U18: =+M18+K18 -> 18 | W18: =+F18-V18 -> 18 | Z18: =+N18+O18 -> 48.6 | AA18: =+Q18+R18 -> 18
A19: COCINA | B19: 1.6 | C19: 2 | D19: 2.7 | E19: =+B19*C19 -> 3.2 | F19: =+(B19+C19)*2 -> 7.2 | G19: =+F19*D19 -> 19.44 | H19: =+G19 -> 19.44 | I19: =+E19 -> 3.2 | M19: =+E19 -> 3.2 | O19: =+G19-T19 -> 16.395 | P19: =+F19 -> 7.2 | R19: =1.6*2+2 -> 5.2 | T19: =+(1.5+0.6)*1.45 -> 3.045 | U19: =+M19+K19 -> 3.2 | W19: =+F19-V19 -> 7.2 | Z19: =+N19+O19 -> 16.395 | AA19: =+Q19+R19 -> 5.2 | AB19: =1.5*0.6 -> 0.9
A20: BAÑO | B20: 1.6 | C20: 2 | D20: 2.7 | E20: =+B20*C20 -> 3.2 | F20: =+(B20+C20)*2 -> 7.2 | G20: =+F20*D20 -> 19.44 | H20: =+G20 -> 19.44 | I20: =+E20 -> 3.2 | M20: =+E20-K20 -> 3.2 | O20: =+F20 -> 7.2 | P20: =+F20 -> 7.2 | R20: =+E20 -> 3.2 | T20: =+F20*2.4 -> 17.28 | U20: =+M20+K20 -> 3.2 | Z20: =+N20+O20 -> 7.2 | AA20: =+Q20+R20 -> 3.2 | AC20: =1.5*0.15*2 -> 0.45
A21: BALCON FRENTE | B21: 1.5 | C21: 3.25 | D21: 2.7 | E21: =+B21*C21 -> 4.875 | F21: =+(B21+C21)*2 -> 9.5 | G21: =+F21*D21 -> 25.65 | I21: =+E21 -> 4.875 | K21: =+E21 -> 4.875 | X21: =+E21 -> 4.875 | Y21: =+F21 -> 9.5
A22: DPTO C | H22: =SUM(H23:H28) -> 153.198 | I22: =SUM(I23:I28) -> 37.7865 | J22: =SUM(J23:J28) -> 0 | K22: =SUM(K23:K28) -> 0 | L22: =SUM(L23:L28) -> 0 | M22: =SUM(M23:M28) -> 37.7865 | N22: =SUM(N23:N28) -> 0 | O22: =SUM(O23:O28) -> 130.558 | ... AC22: =SUM(AC23:AC28) -> 0.45
A23: INGRESO | B23: 0.9 | C23: 1.9 | D23: 2.7 | E23: =+B23*C23 -> 1.71 | F23: =+(B23+C23)*2 -> 5.6 | G23: =+F23*D23 -> 15.12 | H23: =+G23 -> 15.12 | I23: =+E23 -> 1.71 | M23: =+E23 -> 1.71 | O23: =+G23 -> 15.12 | P23: =+F23 -> 5.6 | Q23: =+E23 -> 1.71 | U23: =+M23+K23 -> 1.71 | W23: =+F23-V23 -> 5.6 | Z23: =+N23+O23 -> 15.12 | AA23: =+Q23+R23 -> 1.71
A24: COCINA COMEDOR | B24: 4.11 | C24: 3.6 | D24: 2.7 | E24: =+B24*C24 -> 14.796 | F24: =+(B24+C24)*2 -> 15.42 | G24: =+F24*D24 -> 41.634 | H24: =+G24 -> 41.634 | I24: =+E24 -> 14.796 | M24: =+E24 -> 14.796 | O24: =+G24-T24 -> 36.269 | P24: =+F24 -> 15.42 | Q24: =+E24-2.5*0.6 -> 13.296 | R24: =2.5*0.6+2.5 -> 4 | S24: 2 | T24: =+(0.6*2+2.5)*1.45 -> 5.365 | U24: =+M24+K24 -> 14.796 | W24: =+F24-V24 -> 15.42 | Z24: =+N24+O24 -> 36.269 | AA24: =+Q24+R24 -> 17.296 | AB24: =1.8*0.6 -> 1.08
A25: PASO | B25: 1.7 | C25: 2.8 | D25: 2.7 | E25: =+B25*C25 -> 4.76 | F25: =+(B25+C25)*2 -> 9 | G25: =+F25*D25 -> 24.3 | H25: =+G25 -> 24.3 | I25: =+E25 -> 4.76 | M25: =+E25 -> 4.76 | O25: =+G25-T25 -> 24.3 | P25: =+F25 -> 9 | Q25: =+E25 -> 4.76 | S25: 2 | U25: =+M25+K25 -> 4.76 | W25: =+F25-V25 -> 9 | Z25: =+N25+O25 -> 24.3 | AA25: =+Q25+R25 -> 4.76
A26: BAÑO | B26: 2.5 | C26: 1.6 | D26: 2.7 | E26: =+B26*C26 -> 4 | F26: =+(B26+C26)*2 -> 8.2 | G26: =+F26*D26 -> 22.14 | H26: =+G26 -> 22.14 | I26: =+E26 -> 4 | M26: =+E26-K26 -> 4 | O26: =+F26 -> 8.2 | P26: =+F26 -> 8.2 | R26: =+E26 -> 4 | T26: =+F26*2.4 -> 19.68 | U26: =+M26+K26 -> 4 | Z26: =+N26+O26 -> 8.2 | AA26: =+Q26+R26 -> 4 | AC26: =1.5*0.15*2 -> 0.45
A27: LAVADERO | B27: 1.11 | C27: 1.55 | D27: 2.7 | E27: =+B27*C27 -> 1.7205 | F27: =+(B27+C27)*2 -> 5.32 | G27: =+F27*D27 -> 14.364 | H27: =+G27 -> 14.364 | I27: =+E27 -> 1.7205 | M27: =+E27 -> 1.7205 | O27: =+G27-T27 -> 11.029 | P27: =+F27 -> 5.32 | R27: =+E27 -> 1.7205 | T27: =+(0.6*2+1.1)*1.45 -> 3.335 | U27: =+M27+K27 -> 1.7205 | W27: =+F27-V27 -> 5.32 | Z27: =+N27+O27 -> 11.029 | AA27: =+Q27+R27 -> 1.7205 | AB27: =1.1*0.6 -> 0.66
A28: DORMITORIO | B28: 3 | C28: 3.6 | D28: 2.7 | E28: =+B28*C28 -> 10.8 | F28: =+(B28+C28)*2 -> 13.2 | G28: =+F28*D28 -> 35.64 | H28: =+G28 -> 35.64 | I28: =+E28 -> 10.8 | M28: =+E28 -> 10.8 | O28: =+G28-T28 -> 35.64 | P28: =+F28 -> 13.2 | Q28: =+E28 -> 10.8 | R28: 6 | S28: 1 | U28: =+M28+K28 -> 10.8 | W28: =+F28-V28 -> 13.2 | Z28: =+N28+O28 -> 35.64 | AA28: =+Q28+R28 -> 16.8
A31: PALIER Y ESCALERA | H31: =+H32*11+H33*11.2+H34+H35 -> 823.98 | I31: =+I32*11+I33*11.2+I34+I35 -> 93.8 | J31: =+J32*11+J33*11.2+J34+J35 -> 0 | K31: =+K32*11+K33*11.2+K34+K35 -> 0 | L31: =+L32*11+L33*11.2+L34+L35 -> 150.416 | M31: =+M32*11+M33*11.2+M34+M35 -> 93.8 | N31: =+N32*11+N33*11.2+N34+N35 -> 473.52 | O31: =+O32*11+O33*11.2+O34+O35 -> 350.46 | ... AC31: =+AC32*11+AC33*11.2+AC34+AC35 -> 0
A32: PALIER | B32: 2 | C32: 3.9 | D32: 2.7 | E32: =+B32*C32 -> 7.8 | F32: =+(B32+C32)*2 -> 11.8 | G32: =+F32*D32 -> 31.86 | H32: =+G32 -> 31.86 | I32: =+E32 -> 7.8 | M32: =+E32 -> 7.8 | O32: =+G32-T32 -> 31.86 | P32: =+F32 -> 11.8 | R32: =+E32 -> 7.8 | S32: 14 | U32: =+M32+K32 -> 7.8 | V32: =+F32 -> 11.8 | Z32: =+N32+O32 -> 31.86 | AA32: =+Q32+R32 -> 7.8
A33: ESCALERAS | B33: 4.4 | C33: 2.2 | D33: 3 | E33: =+B33*C33 -> 9.68 | F33: =+(B33+C33)*2 -> 13.2 | G33: =+F33*D33 -> 39.6 | H33: =+G33 -> 39.6 | L33: =+E33+1.25*0.2*15 -> 13.43 | N33: =+G33 -> 39.6 | Q33: =+E33 -> 9.68 | Z33: =+N33+O33 -> 39.6 | AA33: =+Q33+R33 -> 9.68
A34: AZOTEA/TERRAZAS | B34: 8.36 | C34: 7.6 | D34: 2.7 | E34: =+B34*C34-2*5.5 -> 52.536 | F34: =+(B34+C34)*2 -> 31.92 | G34: =+F34*D34 -> 86.184 | Z34: =+N34+O34 -> 0 | AA34: =+Q34+R34 -> 0 | AB34: =1.8*0.6*2 -> 2.16
A35: SALA DE MAQUINAS | B35: 4 | C35: 2 | D35: 2.5 | E35: =+B35*C35 -> 8 | F35: =+(B35+C35)*2 -> 12 | G35: =+F35*D35 -> 30 | H35: =+G35 -> 30 | I35: =+E35 -> 8 | M35: =+E35 -> 8 | N35: =+G35 -> 30 | Q35: =+E35 -> 8 | Z35: =+N35+O35 -> 30 | AA35: =+Q35+R35 -> 8

Sheet Mamposterias
B1: MAMP. LAD. CER. HUECO 18 CM | C1: MAMP. LAD. CER. HUECO DM20 | D1: MAMP. LAD. CER. HUECO 12 CM | E1: MAMP. LAD. CER. HUECO 8 CM | F1: MAMP. LAD. HUECO 8 CM DOBLE | G1: MAMP. LAD. CER. COMUN 30 CM DOBLE
A2: PB | B2: =+(6+2.5)*4 -> 34 | D2: =+(3.3+5.4+3.5+3+1.3+2.7)*4 -> 76.8 | E2: =3.5*4 -> 14 | G2: =+(21.36*2+8.66)*4*0.3 -> 61.656
A3: 1 | B3: =+(7.2+6.4+2)*2.8 -> 43.68 | C3: =+(8.36*2)*2.8-1.5*2*6 -> 28.816 | D3: =+(4.7+1.1+1.8+2.2+4+5.2)*2.8 -> 53.2 | E3: =+(0.4+1+1.5+3.1+4.5+4.1+0.7+1.6+1.7*2+0.4+0.8+2.1+0.7*2+2.6+0.7+1)*2.8 -> 82.04 | G3: =+(18.4*2)*3*0.3 -> 33.12
A4: 2 | B4: =+(7.2+6.4+2)*2.8 -> 43.68 | C4: =+(8.36*2)*2.8-1.5*2*6 -> 28.816 | D4: =+(4.7+1.1+1.8+2.2+4+5.2)*2.8 -> 53.2 | E4: =+(0.4+1+1.5+3.1+4.5+4.1+0.7+1.6+1.7*2+0.4+0.8+2.1+0.7*2+2.6+0.7+1)*2.8 -> 82.04 | G4: =+(18.4*2)*3*0.3 -> 33.12
A5: 3 | B5: =+(7.2+6.4+2)*2.8 -> 43.68 | C5: =+(8.36*2)*2.8-1.5*2*6 -> 28.816 | D5: =+(4.7+1.1+1.8+2.2+4+5.2)*2.8 -> 53.2 | E5: =+(0.4+1+1.5+3.1+4.5+4.1+0.7+1.6+1.7*2+0.4+0.8+2.1+0.7*2+2.6+0.7+1)*2.8 -> 82.04 | G5: =+(18.4*2)*3*0.3 -> 33.12
A6: 4 | B6: =+(7.2+6.4+2)*2.8 -> 43.68 | C6: =+(8.36*2)*2.8-1.5*2*6 -> 28.816 | D6: =+(4.7+1.1+1.8+2.2+4+5.2)*2.8 -> 53.2 | E6: =+(0.4+1+1.5+3.1+4.5+4.1+0.7+1.6+1.7*2+0.4+0.8+2.1+0.7*2+2.6+0.7+1)*2.8 -> 82.04 | G6: =+(18.4*2)*3*0.3 -> 33.12
A7: 5 | B7: =+(6.8+6.4+2)*2.8 -> 42.56 | C7: =+(8.36*2)*2.8-1.5*2*6 -> 28.816 | D7: =+(4.7+1.1+1.8+2.2+4+5.2)*2.8 -> 53.2 | E7: =+(0.4+1+1.5+3+4+2.8+0.7+1.7+2.6+0.4+2.1+0.7*2+2.1+2.7+1)*2.8 -> 76.72 | F7: =+(18.4*2)*2.8 -> 103.04 | G7: =+(18.4*2)*3*0.15 -> 16.56
A8: 6 | B8: =+(5.9+6.4+2)*2.8 -> 40.04 | C8: =+(8.36*2)*2.8-1.5*2*6 -> 28.816 | D8: =+(4.7+1.1+1.8+2.2+4+5.2)*2.8 -> 53.2 | E8: =+(0.4+1+1.5+3+3.1+2.8+0.7+1.7+2.6+0.4+2.1+0.7*2+2.1+2.7+1)*2.8 -> 74.2 | F8: =+(18.4*2)*2.8 -> 103.04 | G8: =+(18.4*2)*3*0.15 -> 16.56
A9: 7 | B9: =+(6.4+2+3.4)*2.8 -> 33.04 | C9: =+(8.36*2)*2.8-1.5*2*5 -> 31.816 | D9: =+(4.7+1.1+1.8+2.2+4+5.2)*2.8 -> 53.2 | E9: =+(0.4+1+1.5+3+4.9+0.3+2.6+0.4+2.1*2+2.2+0.7+2+0.7+2.7+0.7+1)*2.8 -> 79.24 | F9: =+(15.8*2)*2.8 -> 88.48 | G9: =+(15.8*2)*3*0.15 -> 14.22
A10: 8 | B10: =+(6.4+2+3.4)*2.8 -> 33.04 | C10: =+(8.36*2)*2.8-1.5*2*5 -> 31.816 | D10: =+(4.7+1.1+1.8+2.2+4+5.2)*2.8 -> 53.2 | E10: =+(0.4+1+1.5+3+3.9+3+0.4+0.3+2.1+2.1+0.7+2+2.7+0.7+1)*2.8 -> 69.44 | F10: =+(14.9*2)*2.8 -> 83.44 | G10: =+(14.9*2)*3*0.15 -> 13.41
A11: 9 | B11: =+(6.4+2)*2.8 -> 23.52 | C11: =+(8.36*2)*2.8-1.5*2*5 -> 31.816 | D11: =+(4.7+1.1+1.8+2.2+4+5.2)*2.8 -> 53.2 | E11: =+(0.4+1+1.5+3+3+0.7+3+1.7+0.4+1.1+0.7+2+2.7+0.7+1)*2.8 -> 64.12 | F11: =+(14*2)*2.8 -> 78.4 | G11: =+(14*2)*3*0.15 -> 12.6
A12: 10 | B12: =+(6.4)*2.8 -> 17.92 | C12: =+(8.36)*2.8-1.5*2*3 -> 14.408 | D12: =+(4.7+1.1+1.8+2.2+4+5.2+3+3)*2.8 -> 70 | E12: =+(0.4+1+1.5+3+2.2+0.7+2+2.7+0.7+1)*2.8 -> 42.56 | F12: =+(13.1*2)*2.8 -> 73.36 | G12: =+(13.1*2)*3*0.15 -> 11.79
A13: AZOTEA | D13: =+(4.7+1.1+1.8+2.2+4+5.2+3+3+6.4*2)*2.8 -> 105.84 | F13: =+(4.6)*2.8 -> 12.88 | G13: =+(4.6)*3*0.15 -> 2.07
A14: S. MAQ. | G14: =+(3.2+1.7)*2*2.5*0.15 -> 3.675
A15: TOTAL | B15: =SUM(B2:B14) -> 398.84 | C15: =SUM(C2:C14) -> 282.752 | D15: =SUM(D2:D14) -> 731.44 | E15: =SUM(E2:E14) -> 748.44 | F15: =SUM(F2:F14) -> 542.64 | G15: =SUM(G2:G14) -> 285.021
F16: =+E15+F15 -> 1291.08
A19: HORMIGON CIMIENTOS = | D19: =+((D2+E2+G2)/4)*0.4*0.6 -> 9.14736
A21: CAPA AISLADORA = | D21: =+(D2+E2+G2)/4 -> 38.114

Sheet Rev. exterior
A1: REVOQUE EXTERIOR | B1: FRENTES | C1: MEDIANERA | E1: PINTURA EXTERIOR | F1: FRENTE | G1: MEDIANERA | I1: AZOT. IMPERMEABLE + PINTURA ASFALTICA | L1: HORMIGON VISTO | M1: TECHOS + ALEROS | N1: LOSAS TABLA | O1: BARANDAS
A3: PB | E3: PB | F3: =+Albañileria!H4+Albañileria!H5+Albañileria!H6 -> 342.88 | I3: PB | J3: =+(11.5+5.3)*2*4 -> 134.4 | L3: PB
A4: 1 | B4: =+F4 -> 44.16 | E4: 1 | F4: =+(8.96*2+1.4*2)*3-1.5*2*6 -> 44.16 | G4: =18.4*2*3 -> 110.4 | I4: 1 | J4: =+(16.8+8.36)*2*2.8 -> 140.896 | L4: 1 | M4: =1.5*8.36+1.5*1.1*2 -> 15.84 | O4: =+(1.5*2+8.36)*1+(1.5+1.1)*2*1 -> 16.56
A5: 2 | B5: =+F5 -> 44.16 | E5: 2 | F5: =+(8.96*2+1.4*2)*3-1.5*2*6 -> 44.16 | G5: =18.4*2*3 -> 110.4 | I5: 2 | J5: =+(16.8+8.36)*2*2.8 -> 140.896 | L5: 2 | M5: =1.5*8.36+1.5*1.1*2 -> 15.84 | O5: =+(1.5*2+8.36)*1+(1.5+1.1)*2*1 -> 16.56
A6: 3 | B6: =+F6 -> 44.16 | E6: 3 | F6: =+(8.96*2+1.4*2)*3-1.5*2*6 -> 44.16 | G6: =18.4*2*3 -> 110.4 | I6: 3 | J6: =+(16.8+8.36)*2*2.8 -> 140.896 | L6: 3 | M6: =1.5*8.36+1.5*1.1*2 -> 15.84 | O6: =+(1.5*2+8.36)*1+(1.5+1.1)*2*1 -> 16.56
A7: 4 | B7: =+F7 -> 44.16 | E7: 4 | F7: =+(8.96*2+1.4*2)*3-1.5*2*6 -> 44.16 | G7: =18.4*2*3 -> 110.4 | I7: 4 | J7: =+(16.8+8.36)*2*2.8 -> 140.896 | L7: 4 | M7: =1.5*8.36+1.5*1.1*2 -> 15.84 | O7: =+(1.5*2+8.36)*1+(1.5+1.1)*2*1 -> 16.56
A8: 5 | B8: =+F8 -> 47.46 | E8: 5 | F8: =+(8.96*2+1.95*2)*3-1.5*2*6 -> 47.46 | G8: =18.4*2*3 -> 110.4 | I8: 5 | J8: =+(16.2+8.36)*2*2.8 -> 137.536 | L8: 5 | M8: =1.5*8.36+1.5*1.65*2 -> 17.49 | O8: =+(1.5*2+8.36)*1+(1.5+1.65)*2*1 -> 17.66
A9: 6 | B9: =+F9 -> 52.86 | E9: 6 | F9: =+(8.96*2+2.85*2)*3-1.5*2*6 -> 52.86 | G9: =18.4*2*3 -> 110.4 | I9: 6 | J9: =+(15.3+8.36)*2*2.8 -> 132.496 | L9: 6 | M9: =1.5*8.36+(1.5*2.55+0.9*2.68)*2 -> 25.014 | O9: =+(1.5*2+8.36)*1+(8.36+1.8*2)*1 -> 23.32
A10: 7 | B10: =+F10 -> 45.96 | E10: 7 | F10: =+(8.96*2+1.2*2)*3-1.5*2*5 -> 45.96 | G10: =15.7*2*3 -> 94.2 | I10: 7 | J10: =+(14.5+8.36)*2*2.8 -> 128.016 | L10: 7 | M10: =1.5*8.36+0.9*8.36 -> 20.064 | O10: =+(1.5*2+8.36)*1+(8.36)*1 -> 19.72
A11: 8 | B11: =+F11 -> 45.96 | E11: 8 | F11: =+(8.96*2+1.2*2)*3-1.5*2*5 -> 45.96 | G11: =14.9*2*3 -> 89.4 | I11: 8 | J11: =+(13.6+8.36)*2*2.8 -> 122.976 | L11: 8 | M11: =1.5*8.36+0.9*8.36 -> 20.064 | O11: =+(1.5*2+8.36)*1+(8.36)*1 -> 19.72
A12: 9 | B12: =+F12 -> 45.96 | E12: 9 | F12: =+(8.96*2+1.2*2)*3-1.5*2*5 -> 45.96 | G12: =14*2*3 -> 84 | I12: 9 | J12: =+(12.7+8.36)*2*2.8 -> 117.936 | L12: 9 | M12: =1.5*8.36+0.9*8.36 -> 20.064 | O12: =+(1.5*2+8.36)*1+(8.36)*1 -> 19.72
A13: 10 | B13: =+F13 -> 93.36 | E13: 10 | F13: =+(8.96*2+5.1*2+3*2)*3-1.5*2*3 -> 93.36 | G13: =13.1*2*3 -> 78.6 | I13: 10 | J13: =+(10+8.36)*2*2.8 -> 102.816 | L13: 10 | M13: =1.5*8.36 -> 12.54 | O13: =+(1.5*2+8.36)*1 -> 11.36
A14: AZOTEA | B14: =+F14 -> 98.76 | E14: AZOTEA | F14: =+(8.96+7.5)*2*3 -> 98.76 | G14: =13.1*2*3 -> 78.6 | I14: AZOTEA | J14: =+(4.5+5.3)*2*2.8 -> 54.88 | L14: AZOTEA | M14: 39.55
A15: S. MAQ. | B15: =+F15 -> 48 | E15: S. MAQ. | F15: =+(5+5.5*2)*3 -> 48 | G15: =4.5*3 -> 13.5 | I15: S. MAQ. | L15: S. MAQ.
A16: TOTAL | B16: =SUM(B3:B15) -> 654.96 | C16: =SUM(C3:C15) -> 0 | E16: TOTAL | F16: =SUM(F3:F15) -> 997.84 | G16: =SUM(G3:G15) -> 1100.7 | I16: TOTAL | J16: =SUM(J3:J15) -> 1494.64 | L16: TOTAL | M16: =SUM(M3:M15) -> 218.146 | N16: =SUM(N3:N15) -> 0 | O16: =SUM(O3:O15) -> 177.74
O17: =SUM(M16:O16) -> 395.886

Sheet Hormigon
A2: Sup. Cubierta
A3: =8.36*21.36 -> 178.5696 | B3: PB | E3: VOL HORMIGON APROXIMADO
A4: =17.2*8.66+1.65*1.1*2+1.5*8.36 -> 165.122 | B4: 1º | E4: PILOTES | F4: 66.8 | G4: 0.11 | H4: =+C$18*G4 -> 57.250565 | J4: Perforacion pilotes
A5: =17.2*8.66+1.65*1.1*2+1.5*8.36 -> 165.122 | B5: 2º | C5: =+A5*0.25 -> 41.2805 | D5: =+C5*G7 -> 10.320125 | E5: CABEZALES | F5: 31.3 | G5: 0.06 | H5: =+C$18*G5 -> 31.227581
A6: =17.2*8.66+1.65*1.1*2+1.5*8.36 -> 165.122 | B6: 3º | E6: VIGAS DE FUND | F6: 9.4 | G6: 0.04 | H6: =+C$18*G6 -> 20.818387
A7: =17.2*8.66+1.65*1.1*2+1.5*8.36 -> 165.122 | B7: 4º | E7: TABIQUES | F7: 105.18675 | G7: 0.25 | H7: =+C$18*G7 -> 130.11492
A8: =16.7*8.66+1.65*1.65*2+1.5*8.36 -> 162.607 | B8: 5º | E8: VIGAS | F8: 99.932241 | G8: 0.19 | H8: =+C$18*G8 -> 98.887339
A9: =15.8*8.66+1.65*2.55*2+0.9*5.36+1.5*8.36 -> 162.607 | B9: 6º | E9: LOSAS | F9: 162.59301 | G9: 0.35 | H9: =+C$18*G9 -> 182.16089
A10: =14.8*8.66+0.9*8.66+1.5*8.36 -> 148.502 | B10: 7º | F10: =SUM(F4:F9) -> 475.21201 | G10: =SUM(G4:G9) -> 1 | H10: =SUM(H4:H9) -> 520.45968
A11: =14*8.66+0.9*8.66+1.5*8.36 -> 141.574 | B11: 8º
A12: =13.1*8.66+0.9*8.66+1.5*8.36 -> 133.78 | B12: 9º
A13: =10.3*8.66+1.5*8.36 -> 101.738 | B13: 10º
A14: =4.8*5.5+2*3 -> 32.4 | B14: AZ | E14: Perforacion pilotes | H14: =+H4/(3.1416*0.2*0.2)*1.15 -> 523.92212 | I14: =8000*1.2*1.21 -> 11616 | J14: =+I14*H14 -> 6085879.4
A15: =4.2*3 -> 12.6 | B15: SM | E15: Excavacion cab y vf | H15: =+(H5+H6)*1.2*1.25 -> 78.068952 | J15: =+(16000*3*10)*1.2*1.21 -> 696960
A16: =SUM(A3:A15) -> 1734.8656 | J16: =+J15 -> 696960
J17: =SUM(J14:J16) -> 7479799.4
A18: =SUM(A16:A16) -> 1734.8656 | B18: 0.3 | C18: =+A18*B18 -> 520.45968 | J18: =+J17/H14 -> 14276.548
E19: Hormigon h-21 | F19: =80600*1.1*1.21 -> 107278.6 | G19: =+F19*H10+F21*H10+F20*13 -> 65700976
E20: Bomba | F20: =325900*1.1*1.21 -> 433772.9 | G20: =+G19/H10 -> 126236.44
E21: Adic | F21: =+(4717+1386)*1.1*1.21 -> 8123.093
A31: Clavos | B31: 2283.7293 | C31: 944.775 | D31: =+C31*B31 -> 2157610.4
A32: Alambre | B32: 1934.5855 | C32: 1268.54 | D32: =+C32*B32 -> 2454099.1
A33: Fenolicos | B33: 86.86593 | C33: 7750 | D33: =+C33*B33 -> 673210.96 | E33: =+(C33)*15226.8/2399.4 -> 49182.171
A34: Fenolicos film | B34: 161.03752 | C34: 15000 | D34: =+C34*B34 -> 2415562.9 | E34: =+(C34)*15226.8/2399.4 -> 95191.298
A35: Vigas 3x6 | B35: 301.1 | C35: 570.18 | D35: =+C35*B35 -> 171681.2
A36: Tirante 3x3 | B36: 1437.35 | C36: 762.45 | D36: =+C36*B36 -> 1095907.5
A37: Caño pvc 30 cm | B37: 1.1 | C37: 127500 | D37: =+C37*B37 -> 140250
A38: Tabla 1x3 | B38: 400 | C38: 424.32 | D38: =+C38*B38 -> 169728
D39: =SUM(D31:D38) -> 9278050 | E39: =SUM(D33:D38) -> 4666340.5
D40: =+(D39/644)*15226.8/2399.4 -> 91427.497 | E40: =+(E39/644)*15226.8/2399.4 -> 45982.92
E41: =+E40*(H7+H8+H9) -> 18906482
E43: =+(E39)*14214.4/2399.4 -> 27644090
E44: =+(D39)*14214.4/2399.4 -> 54964538

Sheet Instalaciones
A3: Materiales electricos
B4: Electrinet | D4: =586425*1.21 -> 709574.25 | E4: =+D4/18 -> 39420.792 | F4: =+E4*45*1.2 -> 2128722.8 | H4: =+(68721+313322+386524+37486+317980+22835)*1.21*1.5 -> 2081565.4
B5: Artefactos iluminacion | D5: =(8513+21030+2823+20162+9362+9362+14274+14322)*1.21 -> 120816.08 | E5: =+D5/18 -> 6712.0044 | F5: =+E5*45*1.2 -> 362448.24 | H5: =+E5*47*1.5 -> 473196.31
B6: Termotanques | E6: =+D6/18 -> 0 | F6: =+E6*45*1.2 -> 0 | G6: SET
B7: Cocinas electricas | E7: =+D7/18 -> 0 | F7: =+E7*45*1.2 -> 0 | H7: =+#REF! -> #REF! | I7: =+H7+H6 -> #REF!
D8: =SUM(D4:D7) -> 830390.33 | F8: =SUM(F4:F7) -> 2491171 | H8: =SUM(H4:H7) -> #REF!
D9: =+D8*1.1 -> 913429.36 | E9: =+D9/18 -> 50746.076 | F9: =+F8*1.1 -> 2740288.1 | H9: =+H8*1.2 -> #REF! | I9: =+H9/47 -> #REF!
A11: Mano de obra: | B11: Pasquali | D11: 3885800 | E11: =+D11/47 -> 82676.596 | H11: =+D11*1.105*1.5 -> 6440713.5
D12: =+D11*1.21 -> 4701818
D13: =+D12*1.5 -> 7052727 | H13: =+#REF!*1.5 -> #REF!
H14: =SUM(H11:H13) -> #REF! | I14: =+H14+H9 -> #REF! | J14: =+I14/47 -> #REF!
A16: Materiales sanitarios
B17: Cloaca | D17: =(113906+171558)*1.21 -> 345411.44 | E17: =+D17/18 -> 19189.524 | F17: =+E17*46*1.2 -> 1059261.7 | H17: =2203149*1.21*1.1 -> 2932391.3
B18: Agual | D18: =634382*1.21 -> 767602.22 | E18: =+D18/18 -> 42644.568 | F18: =+E18*46*1.2 -> 2353980.1
B19: Losa sanitaria | D19: =+#REF! -> #REF! | F19: =+D19*1.2 -> #REF! | H19: =+#REF!*1.1 -> #REF!
E20: =+D20/18 -> 0 | F20: =+E20*45 -> 0
D21: =SUM(D17:D20) -> #REF! | F21: =SUM(F17:F20) -> #REF! | H21: =SUM(H17:H20) -> #REF!
D22: =+D21*1.1 -> #REF! | F22: =+F21*1.1 -> #REF!
A24: Mano de obra: | B24: Aguilar | D24: =2430000*2 -> 4860000 | E24: 2430000 | H24: =+D26 -> 187500 | I24: =+H24+H21 -> #REF!
H25: =+H24/47 -> 3989.3617 | I25: =+I24/47 -> #REF!
D26: =125000*1.5 -> 187500
D27: =+D26*47 -> 8812500

Sheet Computo
A1: Ítems | B1: U | C1: Cantidad
A2: Tareas preliminares:
A3: Replanteo y nivelación | B3: gl | C3: 1
A4: Demolición y limpieza del terreno | B4: gl | C4: 1
A6: Movimiento de suelos:
A7: Perforación pilotes | B7: ml | C7: =+Hormigon!H14 -> 523.92212
A8: Excavación para cabezales y vigas de fundación | B8: m3 | C8: =+Hormigon!H15 -> 78.068952
A9: Relleno y compactación de excavaciones | B9: m3 | C9: =+(C8-C14)*1.25 -> 32.52873
A11: Estructura resistente:
A12: Picado de paredes para estructura | B12: m2 | C12: =12*4 -> 48
A13: Hormigón armado pilotes | B13: m3 | C13: =+Hormigon!H4 -> 57.250565
A14: Hormigón armado cabezales y vigas de fundación | B14: m3 | C14: =+Hormigon!H5+Hormigon!H6 -> 52.045968
A15: Hormigón armado tabiques y columnas | B15: m3 | C15: =+Hormigon!H7 -> 130.11492
A16: Hormigón armado vigas | B16: m3 | C16: =+Hormigon!H8 -> 98.887339
A17: Hormigón armado losas | B17: m3 | C17: =+Hormigon!H9 -> 182.16089
A18: Hormigón armado escaleras | B18: m3 | C18: =2+1.5*10 -> 17
A19: Superficie de hormigón visto balcones fenolico | B19: m2 | C19: =+'Rev. exterior'!O17 -> 395.886
A20: Hormigón de cascote cimientos | B20: m3 | C20: =+Mamposterias!D19 -> 9.14736
A22: Cubierta de techo:
A23: Cubierta metálica | B23: m2 | C23: =5*8.66 -> 43.3
A25: Mamposterías:
A26: Mampostería de ladrillos comunes doble espesor 15 cm | B26: m3 | C26: =+Mamposterias!G15 -> 285.021
A27: Mampostería de ladrillos cerámicos huecos 18 x 18 x 33 cm | B27: m2 | C27: =+Mamposterias!B15 -> 398.84
A28: Mampostería de ladrillos cerámicos huecos 12 x 18 x 33 cm | B28: m2 | C28: =+Mamposterias!D15 -> 731.44
A29: Mampostería de ladrillos cerámicos huecos 8 x 18 x 33 cm | B29: m2 | C29: =+Mamposterias!F16 -> 1291.08
A31: Aislaciones:
A32: Capa ailadora horizontal | B32: m2 | C32: =+Mamposterias!D21 -> 38.114
A34: Revoques:
A35: Picado de revoques existentes | B35: m2 | C35: =+(21.36*2+8.36)*4 -> 204.32
A36: Azotado impermeable | B36: m2 | C36: =+'Rev. exterior'!J16 -> 1494.64
A37: Revoque grueso interior | B37: m2 | C37: =+Albañileria!H2 -> 1624.042
A38: Revoque grueso fratazado exterior | B38: m2 | C38: =+'Rev. exterior'!B16 -> 654.96
A39: Revoque grueso fratazado exterior medianeras | B39: m2 | C39: =+'Rev. exterior'!C16 -> 0
A40: Enlucido a la cal | B40: m2 | C40: =+Albañileria!N2 -> 516.4
A42: Yesería y Durlock:
A43: Enduido de yeso en paredes | B43: m2 | C43: =+Albañileria!O2 -> 791.382
A44: Cantoneras | B44: u | C44: =+Albañileria!S2 -> 176
A45: Cielorraso aplicado yeso | B45: m2 | C45: =+Albañileria!Q2 -> 191.028
A46: Cielorraso suspendido yeso | B46: m2 | C46: =+Albañileria!R2 -> 257.0901
A47: Corte de pintura perimetral | B47: ml | C47: =+Albañileria!P2 -> 296.18
...

Sheet Analisis
A1: =+(2774*1.2+2500)*2.5 -> 14572
B2: Exclusivo | C2: 50% Sup | D2: Hormigon
A3: PB | B3: =10.1*5.5 -> 55.55 | C3: =21.36*8.66-B3 -> 129.4276 | D3: =14*8.66 -> 121.24
A4: 1 | B4: =14*8.66 -> 121.24 | C4: =1.5*8.36 -> 12.54 | D4: =14*8.66 -> 121.24
A5: 2 | B5: =14*8.66 -> 121.24 | C5: =1.5*8.36 -> 12.54 | D5: =14*8.66 -> 121.24
A6: 3 | B6: =14*8.66 -> 121.24 | C6: =1.5*8.36 -> 12.54 | D6: =14*8.66 -> 121.24
A7: 4 | B7: =14*8.66 -> 121.24 | C7: =1.5*8.36 -> 12.54 | D7: =14*8.66 -> 121.24
A8: 5 | B8: =14*8.66 -> 121.24 | C8: =1.5*8.36 -> 12.54 | D8: =14*8.66 -> 121.24
A9: 6 | B9: =14*8.66 -> 121.24 | C9: =1.5*8.36 -> 12.54 | D9: =14*8.66 -> 121.24
A10: 7 | B10: =14*8.66 -> 121.24 | C10: =1.5*8.36 -> 12.54 | D10: =14*8.66 -> 121.24
A11: 8 | B11: =14*8.66 -> 121.24 | C11: =1.5*8.36 -> 12.54 | D11: =14*8.66 -> 121.24
A12: 9 | B12: =14*8.66 -> 121.24 | C12: =1.5*8.36 -> 12.54 | D12: =14*8.66 -> 121.24
A13: 10 | B13: =14*8.66 -> 121.24 | C13: =1.5*8.36 -> 12.54 | D13: =14*8.66 -> 121.24
A14: Azotea y sm | B14: =4*5.5+3*4.5 -> 35.5 | D14: =+B14+C14 -> 35.5
B15: =SUM(B3:B14) -> 1303.45 | C15: =SUM(C3:C14) -> 254.8276 | D15: =SUM(D3:D14) -> 1369.14
B16: Sup. a construir | C16: =+B15+C15*0.5 -> 1430.8638 | D16: =+D15*0.25 -> 342.285

Sheet Estudio
A1: Cafferata 520
A3: Sup. a construir | B3: Costo por m2 | M3: Exclusivo | N3: 50% Sup | Q3: Gastos y honorarios
A4: =+N17 -> 1443.9638 | B4: =+B5/1300 -> 979.02098 | C4: =+B4*A4 -> 1413670.9 | D4: 24000 | L4: PB | M4: =10.1*5.5 -> 55.55 | N4: =21.36*8.66-M4 -> 129.4276 | Q4: HONORARIOS ARQ | R4: =24*1500*1000 -> 36000000 | S4: =24*1500 -> 36000
B5: =1540000/1.21 -> 1272727.3 | C5: =+(D4*(M9+M10+M11+M12+M13+M14)+D4*0.5*(N9+N10+N11+N12+N13+N14))/1300 -> 14269.292 | D5: Exceptiva ($/m2) | F5: Terreno + Honorarios + Aportes + Tasas | I5: =+C5+C6+C7 -> 349627.27 | L5: 1 | M5: =14*8.66 -> 121.24 | N5: =1.5*8.36+2*1.31 -> 15.16 | Q5: HONORARIOS ING | R5: =(7280000+5950000)*1.7 -> 22491000 | S5: 25000
C6: =+S16 -> 95357.98 | D6: Gastos | F6: Terreno (4 Dptos 1° piso Pellegrini) | I6: =4*60000 -> 240000 | L6: 2 | M6: =14*8.66 -> 121.24 | N6: =1.5*8.36+2*1.31 -> 15.16 | Q6: CERTIFICADO URBANISTICO | R6: =184*50 -> 9200 | S6: =+R6/1300 -> 7.0769231
C7: 240000 | D7: Terreno | F7: Honorarios + Aportes + Tasas | I7: =2*60000 -> 120000 | L7: 3 | M7: =14*8.66 -> 121.24 | N7: =1.5*8.36+2*1.31 -> 15.16 | Q7: CERTIFICADO CATASTRAL | R7: 0 | S7: =+R7/1300 -> 0
C8: =SUM(C4:C7) -> 1763298.1 | D8: Total costo obra | I8: =+I6+I7 -> 360000 | L8: 4 | M8: =14*8.66 -> 121.24 | N8: =1.5*8.36+2*1.31 -> 15.16 | Q8: TASA DE REVISION DE PLANOS | R8: 774000 | S8: =+R8/1300 -> 595.38462
L9: 5 | M9: =14*8.66 -> 121.24 | N9: =1.5*8.36+2*1.31 -> 15.16 | O9: =+M9+N9*0.5 -> 128.82 | Q9: COPIA PLANO ANTERIOR | R9: =30*184 -> 5520 | S9: =+R9/1300 -> 4.2461538
A10: Valor de venta por m2: | C10: 1500 | L10: 6 | M10: =14*8.66 -> 121.24 | N10: =1.5*8.36+2*1.31 -> 15.16 | O10: =+M10+N10*0.5 -> 128.82 | Q10: NUMERACION OFICIAL | R10: =6*184 -> 1104 | S10: =+R10/1300 -> 0.84923077
L11: 7 | M11: =14*8.66 -> 121.24 | N11: =1.5*8.36+2*1.31 -> 15.16 | O11: =+M11+N11*0.5 -> 128.82 | Q11: FACTIBILIDAD EPE | R11: 350000 | S11: =+R11/1300 -> 269.23077
A12: Unidades | B12: Precio venta | F12: Exclusivo | G12: Balcon | H12: Total | L12: 8 | M12: =14*8.66 -> 121.24 | N12: =1.5*8.36+2*1.31 -> 15.16 | O12: =+M12+N12*0.5 -> 128.82 | Q12: CONTRIBUCION APROV. ALTURA | R12: =765*24000 -> 18360000 | S12: =+R12/1300 -> 14123.077
A13: 3 | B13: 15000 | C13: =+B13*A13 -> 45000 | D13: Cochera | E13: Planta baja | L13: 9 | M13: =14*8.66 -> 121.24 | N13: =1.5*8.36+2*1.31 -> 15.16 | O13: =+M13+N13*0.5 -> 128.82 | Q13: PERMISO | R13: =35*184 -> 6440 | S13: =+R13/1300 -> 4.9538462
A14: 1 | B14: 45000 | C14: =+B14*A14 -> 45000 | D14: Local PB | F14: =5.5*2.7 -> 14.85 | H14: =SUM(F14:G14) -> 14.85 | I14: =+H14*A14 -> 14.85 | L14: 10 | M14: =14*8.66 -> 121.24 | N14: =1.5*8.36+2*1.31 -> 15.16 | O14: =+M14+N14*0.5 -> 128.82 | Q14: APORTES COLEGI Y CAJA | R14: =3019463.07*2+7850603.97 -> 13889530 | S14: =+R14/1300 -> 10684.254
A15: 3 | B15: =+H15*C$10 -> 59011.579 | C15: =+B15*A15 -> 177034.74 | D15: A 1 Dormitorio | E15: 1° al 3° Piso | F15: =5.8*5.4-0.3/3.8 -> 31.241053 | G15: =1.5*5.4 -> 8.1 | H15: =SUM(F15:G15) -> 39.341053 | I15: =+H15*A15 -> 118.02316 | J15: =+B15/H15 -> 1500 | L15: Azotea y sm | M15: =4*5.5+3*4.5 -> 35.5 | O15: =+M15+N15*0.5 -> 35.5 | R15: =SUM(R4:R14) -> 91886794 | S15: =SUM(S4:S14) -> 86689.072
A16: 3 | B16: =+H16*C$10 -> 48225 | C16: =+B16*A16 -> 144675 | D16: B Monoambiente | F16: =9.6*3.25-3.5*1.1 -> 27.35 | G16: =1.5*3.2 -> 4.8 | H16: =SUM(F16:G16) -> 32.15 | I16: =+H16*A16 -> 96.45 | J16: =+B16/H16 -> 1500 | M16: =SUM(M4:M15) -> 1303.45 | N16: =SUM(N4:N15) -> 281.0276 | O16: =SUM(O9:O15) -> 808.42 | Q16: Imprevistos 10% | R16: =+R15*1.1 -> 1.0107547e+08 | S16: =+S15*1.1 -> 95357.98
A17: 3 | B17: =+H17*C$10 -> 64749 | C17: =+B17*A17 -> 194247 | D17: C 1 Dormitorio | F17: =4.4*8.66+1.8*1.05+1.7*1.26-0.3*1.7-0.45*2.4 -> 40.546 | G17: 2.62 | H17: =SUM(F17:G17) -> 43.166 | I17: =+H17*A17 -> 129.498 | J17: =+B17/H17 -> 1500 | M17: Sup. a construir | N17: =+M16+N16*0.5 -> 1443.9638
A18: 3 | B18: =+H18*C$10*1.02 -> 60191.811 | C18: =+B18*A18 -> 180575.43 | D18: A 1 Dormitorio | E18: 4° al 6° Piso | F18: =5.8*5.4-0.3/3.8 -> 31.241053 | G18: =1.5*5.4 -> 8.1 | H18: =SUM(F18:G18) -> 39.341053 | I18: =+H18*A18 -> 118.02316 | J18: =+B18/H18 -> 1530
A19: 3 | B19: =+H19*C$10*1.02 -> 49189.5 | C19: =+B19*A19 -> 147568.5 | D19: B Monoambiente | F19: =9.6*3.25-3.5*1.1 -> 27.35 | G19: =1.5*3.2 -> 4.8 | H19: =SUM(F19:G19) -> 32.15 | I19: =+H19*A19 -> 96.45 | J19: =+B19/H19 -> 1530 | M19: =SUM(M9:M14)+(SUM(N9:N14)*0.5) -> 772.92
A20: 3 | B20: =+H20*C$10*1.05 -> 67986.45 | C20: =+B20*A20 -> 203959.35 | D20: D 1 Dormitorio | F20: =4.4*8.66+1.8*1.05+1.7*1.26-0.3*1.7-0.45*2.4 -> 40.546 | G20: 2.62 | H20: =SUM(F20:G20) -> 43.166 | I20: =+H20*A20 -> 129.498 | J20: =+B20/H20 -> 1575 | L20: Exclusiva | N20: =+M16 -> 1303.45
A21: 3 | B21: =+H21*C$10*1.04 -> 61372.042 | C21: =+B21*A21 -> 184116.13 | D21: A 1 Dormitorio | E21: 7° al 9° Piso | F21: =5.8*5.4-0.3/3.8 -> 31.241053 | G21: =1.5*5.4 -> 8.1 | H21: =SUM(F21:G21) -> 39.341053 | I21: =+H21*A21 -> 118.02316 | J21: =+B21/H21 -> 1560 | L21: Semicubierta | N21: =+N16-N22 -> 151.6
A22: 3 | B22: =+H22*C$10*1.04 -> 50154 | C22: =+B22*A22 -> 150462 | D22: B Monoambiente | F22: =9.6*3.25-3.5*1.1 -> 27.35 | G22: =1.5*3.2 -> 4.8 | H22: =SUM(F22:G22) -> 32.15 | I22: =+H22*A22 -> 96.45 | J22: =+B22/H22 -> 1560 | L22: Cochera | N22: =+N4 -> 129.4276
A23: 3 | B23: =+H23*C$10*1.04 -> 67338.96 | C23: =+B23*A23 -> 202016.88 | D23: C 1 Dormitorio | F23: =4.4*8.66+1.8*1.05+1.7*1.26-0.3*1.7-0.45*2.4 -> 40.546 | G23: 2.62 | H23: =SUM(F23:G23) -> 43.166 | I23: =+H23*A23 -> 129.498 | J23: =+B23/H23 -> 1560
A24: 1 | B24: =+H24*C$10*1.06+8000 -> 70552.274 | C24: =+B24*A24 -> 70552.274 | D24: A 1 Dormitorio c/t | E24: 10° Piso | F24: =5.8*5.4-0.3/3.8 -> 31.241053 | G24: =1.5*5.4 -> 8.1 | H24: =SUM(F24:G24) -> 39.341053 | I24: =+H24*A24 -> 39.341053 | J24: =+B24/H24 -> 1793.3499
A25: 1 | B25: =+H25*C$10*1.06 -> 51118.5 | C25: =+B25*A25 -> 51118.5 | D25: B Monoambiente | F25: =9.6*3.25-3.5*1.1 -> 27.35 | G25: =1.5*3.2 -> 4.8 | H25: =SUM(F25:G25) -> 32.15 | I25: =+H25*A25 -> 32.15 | J25: =+B25/H25 -> 1590
A26: 1 | B26: =+H26*C$10*1.06+8000 -> 76633.94 | C26: =+B26*A26 -> 76633.94 | D26: C 1 Dormitorio c/t | F26: =4.4*8.66+1.8*1.05+1.7*1.26-0.3*1.7-0.45*2.4 -> 40.546 | G26: 2.62 | H26: =SUM(F26:G26) -> 43.166 | I26: =+H26*A26 -> 43.166 | J26: =+B26/H26 -> 1775.331
A27: =SUM(A15:A26) -> 30 | B27: Unidades | C27: =SUM(C13:C26) -> 1872959.7 | D27: Total por venta estimado | H27: =SUM(H15:H26) -> 458.62821 | I27: =SUM(I14:I26) -> 1161.4205
A30: Total por venta = | C30: =+(C27/C8-1) -> 0.062191193 | D30: Rendimiento esparado | F30: Costo total por m2 = | I30: =+C8/I27 -> 1518.2254
A31: Total costo obra | F31: Valor de venta por m2 = | I31: =+I30*1.2 -> 1821.8705
C33: =+C4+I5 -> 1763298.1
C34: =+C33/I27 -> 1518.2254
